Workbook

Sheet Lees mij
B1: Meta-advertenties decembercampagne "Buddy houdt het lijstje bij": planning
B3: Wat is dit
B4: Het schema, de advertentielijst, het meetplan en de rekensom bij december/META-ADS-PLAN.md. Het plan legt het waarom uit, dit bestand rekent en houdt bij.
B6: Zo gebruik je het
B7: 1. Zet in 'Instellingen' de echte pot (cel B4). Alle dagbudgetten in 'Kalender' en de rekensom passen zich aan.
B8: 2. Gele cellen met blauwe tekst zijn invoer. Zwarte cellen zijn formules: niet overschrijven.
B9: 3. 'Advertenties': vul per advertentie uitgegeven bedrag, landingspaginaweergaven, starts en aankopen in. Kolom 'Beslissing' geeft de regel uit het plan.
B10: 4. 'Meetplan': vul elke maandag de weekcijfers in (Meta 7 dagen klik, GA4 en Mollie/Supabase naast elkaar, nooit optellen).
B11: 5. 'Preflight': alle regels groen voor de eerste euro wordt uitgegeven.
B13: Aannames die ik niet kon controleren (vervang ze zodra je het weet)
B14: - Pot december: EUR 400 van het masterplan-budget van EUR 508. De rest (EUR 108) is bedoeld voor de zorgpremie-test van 12 november. Werkelijke bestedingen tot nu toe zijn onbekend.
B15: - Standard EUR 3,49 incl. btw per maand (21 % btw). Brutomarge 85 % is een aanname (Mollie-kosten, hosting): echte marge ontbreekt.
... B21: Campagnebestand (Untitled.md), changelog BetaalBuddy van 19 oktober 2026 (masterplan, Clarity- en GA4-cijfers), de ads-skills (Meta Andromeda-playbook, Meta decision system).

Sheet Instellingen
A1: Instellingen en budgetverdeling
A2: Gele cellen met blauwe tekst zijn invoer. Bedragen in euro.
A4: Pot december (EUR) | B4: 400 | C4: Aanname: EUR 508 masterplan min EUR 108 voor de test van 12 nov. Vervang door het echte restbudget.
A5: Prijs Standard per maand incl. btw (EUR) | B5: 3.49 | C5: Campagnebestand: alleen Standard noemen.
A6: Btw | B6: 0.21 | C6: Nederlands standaardtarief.
A7: Opbrengst per maand excl. btw (EUR) | B7: =B5/(1+B6) -> 2.8842975 | C7: Formule: prijs / (1 + btw).
A8: Brutomarge op abonnement | B8: 0.85 | C8: AANNAME: Mollie-kosten per betaling en hosting zijn niet verwerkt. Echte marge ontbreekt.
A9: Doel: kosten per 'Start aanmelding' (EUR) | B9: 15 | C9: Masterplan: minstens 1 checkout per EUR 15. Dit is het anker voor alle beslisregels.
A10: Max kosten per echte bezoeker (EUR) | B10: 1.5 | C10: Masterplan-toets per twee weken.
A11: Min. link-CTR | B11: 0.008 | C11: Masterplan-toets per twee weken.
A12: Min. hook rate (3-seconden-weergaven / vertoningen) | B12: 0.3 | C12: Campagnebestand: organisch meer dan 30 % kijkt 3 seconden. Zelfde drempel voor de betaalde hooktest.
A13: Checkout naar betaald | B13: 0.35 | C13: AANNAME. Wordt na de eerste 10 checkouts vervangen door de echte waarde.
A14: Referral vrijgegeven? (20+ klanten) | B14: Nee | C14: Ja/Nee. Bij Nee gaat het referral-budget naar retargeting.
A16: Verdeling pot over lagen | B16: Aandeel | C16: Bedrag
A17: Bereik (TOFU) | B17: 0.65 | C17: =$B$4*B17 -> 260 | D17: Campagnebestand: 60 / 25 / 15. Afwijking uitgelegd in het plan (sectie 5).
A18: Retargeting (BOFU) | B18: 0.27 | C18: =$B$4*B18 -> 108
A19: Doorverwijzen (voorwaardelijk) | B19: 0.08 | C19: =$B$4*B19 -> 32
A20: Controle: som is 100 % | B20: =B17+B18+B19 -> 1
A22: Effectieve potten | B22: Bedrag
A23: Bereik | B23: =C17 -> 260
A24: Retargeting (incl. niet vrijgegeven referral) | B24: =C18+IF(B14="Ja",0,C19) -> 140
A25: Doorverwijzen | B25: =IF(B14="Ja",C19,0) -> 0
A26: Totaal (moet gelijk zijn aan de pot) | B26: =B23+B24+B25 -> 400 | C26: =IF(ROUND(B26-B4,2)=0,"OK","FOUT: verdeling klopt niet") -> OK
A28: Fasen en budgetritme
A29: Fase | B29: Start | C29: Eind | D29: Bereik start | E29: Bereik eind | F29: RT start | G29: RT eind | H29: Ref start | I29: Ref eind | J29: Aandeel bereik | K29: Aandeel RT | L29: Aandeel ref | M29: Bereik EUR | N29: RT EUR | O29: Ref EUR | P29: Bereik / dag | Q29: RT / dag | R29: Ref / dag
A30: F0 Voorbereiding | B30: 46349 | C30: 46355 | D30: 46349 | E30: 46355 | F30: 46349 | G30: 46355 | H30: 46349 | I30: 46355 | J30: 0 | K30: 0 | L30: 0 | M30: =J30*$B$23 -> 0 | N30: =K30*$B$24 -> 0 | O30: =L30*$B$25 -> 0 | P30: =IF(M30=0,0,M30/(E30-D30+1)) -> 0 | Q30: =IF(N30=0,0,N30/(G30-F30+1)) -> 0 | R30: =IF(O30=0,0,O30/(I30-H30+1)) -> 0
A31: F1 Na Black Friday en lijstjestijd | B31: 46356 | C31: 46362 | D31: 46356 | E31: 46362 | F31: 46359 | G31: 46362 | H31: 46356 | I31: 46362 | J31: 0.28 | K31: 0.1 | L31: 0 | M31: =J31*$B$23 -> 72.8 | N31: =K31*$B$24 -> 14 | O31: =L31*$B$25 -> 0 | P31: =IF(M31=0,0,M31/(E31-D31+1)) -> 10.4 | Q31: =IF(N31=0,0,N31/(G31-F31+1)) -> 3.5 | R31: =IF(O31=0,0,O31/(I31-H31+1)) -> 0
A32: F2 Volle agenda | B32: 46363 | C32: 46369 | D32: 46363 | E32: 46369 | F32: 46363 | G32: 46369 | H32: 46363 | I32: 46369 | J32: 0.26 | K32: 0.25 | L32: 0 | M32: =J32*$B$23 -> 67.6 | N32: =K32*$B$24 -> 35 | O32: =L32*$B$25 -> 0 | P32: =IF(M32=0,0,M32/(E32-D32+1)) -> 9.6571429 | Q32: =IF(N32=0,0,N32/(G32-F32+1)) -> 5 | R32: =IF(O32=0,0,O32/(I32-H32+1)) -> 0
A33: F3 Vriendenweek en eindsprint | B33: 46370 | C33: 46375 | D33: 46370 | E33: 46375 | F33: 46370 | G33: 46375 | H33: 46371 | I33: 46375 | J33: 0.21 | K33: 0.35 | L33: 1 | M33: =J33*$B$23 -> 54.6 | N33: =K33*$B$24 -> 49 | O33: =L33*$B$25 -> 0 | P33: =IF(M33=0,0,M33/(E33-D33+1)) -> 9.1 | Q33: =IF(N33=0,0,N33/(G33-F33+1)) -> 8.1666667 | R33: =IF(O33=0,0,O33/(I33-H33+1)) -> 0
A34: F4 Kerst (na het doel van 19 dec) | B34: 46376 | C34: 46381 | D34: 46376 | E34: 46378 | F34: 46376 | G34: 46381 | H34: 46376 | I34: 46381 | J34: 0.04 | K34: 0.15 | L34: 0 | M34: =J34*$B$23 -> 10.4 | N34: =K34*$B$24 -> 21 | O34: =L34*$B$25 -> 0 | P34: =IF(M34=0,0,M34/(E34-D34+1)) -> 3.4666667 | Q34: =IF(N34=0,0,N34/(G34-F34+1)) -> 3.5 | R34: =IF(O34=0,0,O34/(I34-H34+1)) -> 0
A35: F5 Januari klaarzetten | B35: 46382 | C35: 46391 | D35: 46382 | E35: 46391 | F35: 46382 | G35: 46391 | H35: 46382 | I35: 46391 | J35: 0.21 | K35: 0.15 | L35: 0 | M35: =J35*$B$23 -> 54.6 | N35: =K35*$B$24 -> 21 | O35: =L35*$B$25 -> 0 | P35: =IF(M35=0,0,M35/(E35-D35+1)) -> 5.46 | Q35: =IF(N35=0,0,N35/(G35-F35+1)) -> 2.1 | R35: =IF(O35=0,0,O35/(I35-H35+1)) -> 0
A36: Controle: aandelen per laag | J36: =SUM(J30:J35) -> 1 | K36: =SUM(K30:K35) -> 1 | L36: =SUM(L30:L35) -> 1
A37: Totaal fasebudget | M37: =SUM(M30:M35) -> 260 | N37: =SUM(N30:N35) -> 140 | O37: =SUM(O30:O35) -> 0
A38: Elke laag moet op 100 % uitkomen (J36 t/m L36).

Sheet Kalender
A1: Dag-voor-dag schema 23 november t/m 4 januari
A2: Budgetten komen uit 'Instellingen' (pot en verdeling). Organisch volgt de postplanning van het campagnebestand.
A4: Datum | B4: Dag | C4: Fase | D4: Organisch (campagnebestand) | E4: Betaald: wat gebeurt er | F4: Bereik EUR | G4: RT EUR | H4: Ref EUR | I4: Totaal EUR | J4: Cumulatief EUR | K4: % pot | L4: Ritme | M4: Checkpoint of opmerking
A5: 46349 | B5: ma | C5: =INDEX(Instellingen!$A$30:$A$35,MATCH(A5,Instellingen!$B$30:$B$35,1)) -> F0 Voorbereiding | D5: Nog geen feedpost. Story-reeks start 1 dec. | E5: Poortcheck G1: audiences aangemaakt, concepten ingediend voor review, testbetaling in de Instagram-browser. Geen uitgaven. | F5: =SUMPRODUCT((A5>=Instellingen!$D$30:$D$35)*(A5<=Instellingen!$E$30:$E$35)*Instellingen!$P$30:$P$35) -> 0 | G5: =SUMPRODUCT((A5>=Instellingen!$F$30:$F$35)*(A5<=Instellingen!$G$30:$G$35)*Instellingen!$Q$30:$Q$35) -> 0 | H5: =SUMPRODUCT((A5>=Instellingen!$H$30:$H$35)*(A5<=Instellingen!$I$30:$I$35)*Instellingen!$R$30:$R$35) -> 0 | I5: =SUM(F5:H5) -> 0 | J5: =SUM($I$5:I5) -> 0 | K5: =IF(Instellingen!$B$4=0,0,J5/Instellingen!$B$4) -> 0 | L5: Beslisdag | M5: Go/No-go-moment 1
A6: 46350 | B6: di | C6: =INDEX(Instellingen!$A$30:$A$35,MATCH(A6,Instellingen!$B$30:$B$35,1)) -> F0 Voorbereiding | D6: - | E6: Advertenties en retargeting-concepten gepauzeerd klaarzetten zodat Meta ze kan beoordelen (review kan 24 uur duren). | F6: =SUMPRODUCT((A6>=Instellingen!$D$30:$D$35)*(A6<=Instellingen!$E$30:$E$35)*Instellingen!$P$30:$P$35) -> 0 | G6: =SUMPRODUCT((A6>=Instellingen!$F$30:$F$35)*(A6<=Instellingen!$G$30:$G$35)*Instellingen!$Q$30:$Q$35) -> 0 | H6: =SUMPRODUCT((A6>=Instellingen!$H$30:$H$35)*(A6<=Instellingen!$I$30:$I$35)*Instellingen!$R$30:$R$35) -> 0 | I6: =SUM(F6:H6) -> 0 | J6: =SUM($I$5:I6) -> 0 | K6: =IF(Instellingen!$B$4=0,0,J6/Instellingen!$B$4) -> 0
A7: 46351 | B7: wo | C7: =INDEX(Instellingen!$A$30:$A$35,MATCH(A7,Instellingen!$B$30:$B$35,1)) -> F0 Voorbereiding | D7: - | E7: Pixel en CAPI-eindtest: echte testbetaling op iOS en Android, daarna Test Events controleren. | F7: =SUMPRODUCT((A7>=Instellingen!$D$30:$D$35)*(A7<=Instellingen!$E$30:$E$35)*Instellingen!$P$30:$P$35) -> 0 | G7: =SUMPRODUCT((A7>=Instellingen!$F$30:$F$35)*(A7<=Instellingen!$G$30:$G$35)*Instellingen!$Q$30:$Q$35) -> 0 | H7: =SUMPRODUCT((A7>=Instellingen!$H$30:$H$35)*(A7<=Instellingen!$I$30:$I$35)*Instellingen!$R$30:$R$35) -> 0 | I7: =SUM(F7:H7) -> 0 | J7: =SUM($I$5:I7) -> 0 | K7: =IF(Instellingen!$B$4=0,0,J7/Instellingen!$B$4) -> 0 | L7: Lanceerdag
A8: 46352 | B8: do | C8: =INDEX(Instellingen!$A$30:$A$35,MATCH(A8,Instellingen!$B$30:$B$35,1)) -> F0 Voorbereiding | D8: - | E8: UTM-linkcheck, GA4-filter intern verkeer, uitgavenlimiet op het advertentieaccount gelijk aan de pot. | F8: =SUMPRODUCT((A8>=Instellingen!$D$30:$D$35)*(A8<=Instellingen!$E$30:$E$35)*Instellingen!$P$30:$P$35) -> 0 | G8: =SUMPRODUCT((A8>=Instellingen!$F$30:$F$35)*(A8<=Instellingen!$G$30:$G$35)*Instellingen!$Q$30:$Q$35) -> 0 | H8: =SUMPRODUCT((A8>=Instellingen!$H$30:$H$35)*(A8<=Instellingen!$I$30:$I$35)*Instellingen!$R$30:$R$35) -> 0 | I8: =SUM(F8:H8) -> 0 | J8: =SUM($I$5:I8) -> 0 | K8: =IF(Instellingen!$B$4=0,0,J8/Instellingen!$B$4) -> 0
A9: 46353 | B9: vr | C9: =INDEX(Instellingen!$A$30:$A$35,MATCH(A9,Instellingen!$B$30:$B$35,1)) -> F0 Voorbereiding | D9: - | E9: Black Friday: niet adverteren (veiling duurder, funnel nog onbewezen). Laatste Go/No-go voor 30 nov. | F9: =SUMPRODUCT((A9>=Instellingen!$D$30:$D$35)*(A9<=Instellingen!$E$30:$E$35)*Instellingen!$P$30:$P$35) -> 0 | G9: =SUMPRODUCT((A9>=Instellingen!$F$30:$F$35)*(A9<=Instellingen!$G$30:$G$35)*Instellingen!$Q$30:$Q$35) -> 0 | H9: =SUMPRODUCT((A9>=Instellingen!$H$30:$H$35)*(A9<=Instellingen!$I$30:$I$35)*Instellingen!$R$30:$R$35) -> 0 | I9: =SUM(F9:H9) -> 0 | J9: =SUM($I$5:I9) -> 0 | K9: =IF(Instellingen!$B$4=0,0,J9/Instellingen!$B$4) -> 0 | L9: Schaaldag | M9: Go/No-go-moment 2
A10: 46354 | B10: za | C10: =INDEX(Instellingen!$A$30:$A$35,MATCH(A10,Instellingen!$B$30:$B$35,1)) -> F0 Voorbereiding | D10: #1 Eén dag gekocht, negen dagen betalen (Reel) | E10: Alleen meten: weergaven en 3-seconden-kijkers van de organische Reel. Geen budget. | F10: =SUMPRODUCT((A10>=Instellingen!$D$30:$D$35)*(A10<=Instellingen!$E$30:$E$35)*Instellingen!$P$30:$P$35) -> 0 | G10: =SUMPRODUCT((A10>=Instellingen!$F$30:$F$35)*(A10<=Instellingen!$G$30:$G$35)*Instellingen!$Q$30:$Q$35) -> 0 | H10: =SUMPRODUCT((A10>=Instellingen!$H$30:$H$35)*(A10<=Instellingen!$I$30:$I$35)*Instellingen!$R$30:$R$35) -> 0 | I10: =SUM(F10:H10) -> 0 | J10: =SUM($I$5:I10) -> 0 | K10: =IF(Instellingen!$B$4=0,0,J10/Instellingen!$B$4) -> 0
A11: 46355 | B11: zo | C11: =INDEX(Instellingen!$A$30:$A$35,MATCH(A11,Instellingen!$B$30:$B$35,1)) -> F0 Voorbereiding | D11: - | E11: Organische cijfers #1 verzamelen. | F11: =SUMPRODUCT((A11>=Instellingen!$D$30:$D$35)*(A11<=Instellingen!$E$30:$E$35)*Instellingen!$P$30:$P$35) -> 0 | G11: =SUMPRODUCT((A11>=Instellingen!$F$30:$F$35)*(A11<=Instellingen!$G$30:$G$35)*Instellingen!$Q$30:$Q$35) -> 0 | H11: =SUMPRODUCT((A11>=Instellingen!$H$30:$H$35)*(A11<=Instellingen!$I$30:$I$35)*Instellingen!$R$30:$R$35) -> 0 | I11: =SUM(F11:H11) -> 0 | J11: =SUM($I$5:I11) -> 0 | K11: =IF(Instellingen!$B$4=0,0,J11/Instellingen!$B$4) -> 0
A12: 46356 | B12: ma | C12: =INDEX(Instellingen!$A$30:$A$35,MATCH(A12,Instellingen!$B$30:$B$35,1)) -> F1 Na Black Friday en lijstjestijd | D12: - | E12: BESLISDAG. Lees #1 (48 uur organisch). Start Bereik-campagne (Test, CBO) met A1. Controleer dat de retargeting-doelgroepen minstens 100 mensen tellen. | F12: =SUMPRODUCT((A12>=Instellingen!$D$30:$D$35)*(A12<=Instellingen!$E$30:$E$35)*Instellingen!$P$30:$P$35) -> 10.4 | G12: =SUMPRODUCT((A12>=Instellingen!$F$30:$F$35)*(A12<=Instellingen!$G$30:$G$35)*Instellingen!$Q$30:$Q$35) -> 0 | H12: =SUMPRODUCT((A12>=Instellingen!$H$30:$H$35)*(A12<=Instellingen!$I$30:$I$35)*Instellingen!$R$30:$R$35) -> 0 | I12: =SUM(F12:H12) -> 10.4 | J12: =SUM($I$5:I12) -> 10.4 | K12: =IF(Instellingen!$B$4=0,0,J12/Instellingen!$B$4) -> 0.026 | L12: Beslisdag | M12: Start betaald
A13: 46357 | B13: di | C13: =INDEX(Instellingen!$A$30:$A$35,MATCH(A13,Instellingen!$B$30:$B$35,1)) -> F1 Na Black Friday en lijstjestijd | D13: #2 De adventskalender (Reel). Story-deurtje 1 (dagelijks t/m 24 dec) | E13: A2 (hero) in review. Organische proef van de Reel loopt. | F13: =SUMPRODUCT((A13>=Instellingen!$D$30:$D$35)*(A13<=Instellingen!$E$30:$E$35)*Instellingen!$P$30:$P$35) -> 10.4 | G13: =SUMPRODUCT((A13>=Instellingen!$F$30:$F$35)*(A13<=Instellingen!$G$30:$G$35)*Instellingen!$Q$30:$Q$35) -> 0 | H13: =SUMPRODUCT((A13>=Instellingen!$H$30:$H$35)*(A13<=Instellingen!$I$30:$I$35)*Instellingen!$R$30:$R$35) -> 0 | I13: =SUM(F13:H13) -> 10.4 | J13: =SUM($I$5:I13) -> 20.8 | K13: =IF(Instellingen!$B$4=0,0,J13/Instellingen!$B$4) -> 0.052
A14: 46358 | B14: wo | C14: =INDEX(Instellingen!$A$30:$A$35,MATCH(A14,Instellingen!$B$30:$B$35,1)) -> F1 Na Black Friday en lijstjestijd | D14: #4 Het Buddy-rijm (carrousel, alleen organisch) | E14: LANCEERDAG. A2 (Advent-Reel) en A3 (Sint) naar de Test-campagne. Maximaal 3 advertenties tegelijk. | F14: =SUMPRODUCT((A14>=Instellingen!$D$30:$D$35)*(A14<=Instellingen!$E$30:$E$35)*Instellingen!$P$30:$P$35) -> 10.4 | G14: =SUMPRODUCT((A14>=Instellingen!$F$30:$F$35)*(A14<=Instellingen!$G$30:$G$35)*Instellingen!$Q$30:$Q$35) -> 0 | H14: =SUMPRODUCT((A14>=Instellingen!$H$30:$H$35)*(A14<=Instellingen!$I$30:$I$35)*Instellingen!$R$30:$R$35) -> 0 | I14: =SUM(F14:H14) -> 10.4 | J14: =SUM($I$5:I14) -> 31.2 | K14: =IF(Instellingen!$B$4=0,0,J14/Instellingen!$B$4) -> 0.078 | L14: Lanceerdag
A15: 46359 | B15: do | C15: =INDEX(Instellingen!$A$30:$A$35,MATCH(A15,Instellingen!$B$30:$B$35,1)) -> F1 Na Black Friday en lijstjestijd | D15: #3 Sint heeft zijn boek (Reel). #6 Brief van de maker (static) | E15: Retargeting start: B1 (Brief van de maker) met laag budget om de pool te voeden. | F15: =SUMPRODUCT((A15>=Instellingen!$D$30:$D$35)*(A15<=Instellingen!$E$30:$E$35)*Instellingen!$P$30:$P$35) -> 10.4 | G15: =SUMPRODUCT((A15>=Instellingen!$F$30:$F$35)*(A15<=Instellingen!$G$30:$G$35)*Instellingen!$Q$30:$Q$35) -> 3.5 | H15: =SUMPRODUCT((A15>=Instellingen!$H$30:$H$35)*(A15<=Instellingen!$I$30:$I$35)*Instellingen!$R$30:$R$35) -> 0 | I15: =SUM(F15:H15) -> 13.9 | J15: =SUM($I$5:I15) -> 45.1 | K15: =IF(Instellingen!$B$4=0,0,J15/Instellingen!$B$4) -> 0.11275
A16: 46360 | B16: vr | C16: =INDEX(Instellingen!$A$30:$A$35,MATCH(A16,Instellingen!$B$30:$B$35,1)) -> F1 Na Black Friday en lijstjestijd | D16: Story-deurtje | E16: SCHAALDAG. Dag-3 hook rate van A1, A2 en A3 lezen. Frequentie controleren. Nog geen budgetverhoging. | F16: =SUMPRODUCT((A16>=Instellingen!$D$30:$D$35)*(A16<=Instellingen!$E$30:$E$35)*Instellingen!$P$30:$P$35) -> 10.4 | G16: =SUMPRODUCT((A16>=Instellingen!$F$30:$F$35)*(A16<=Instellingen!$G$30:$G$35)*Instellingen!$Q$30:$Q$35) -> 3.5 | H16: =SUMPRODUCT((A16>=Instellingen!$H$30:$H$35)*(A16<=Instellingen!$I$30:$I$35)*Instellingen!$R$30:$R$35) -> 0 | I16: =SUM(F16:H16) -> 13.9 | J16: =SUM($I$5:I16) -> 59 | K16: =IF(Instellingen!$B$4=0,0,J16/Instellingen!$B$4) -> 0.1475 | L16: Schaaldag
A17: 46361 | B17: za | C17: =INDEX(Instellingen!$A$30:$A$35,MATCH(A17,Instellingen!$B$30:$B$35,1)) -> F1 Na Black Friday en lijstjestijd | D17: Pakjesavond. Story-deurtje | E17: A3 (Sint) stopt om 23:59: thema verloopt. | F17: =SUMPRODUCT((A17>=Instellingen!$D$30:$D$35)*(A17<=Instellingen!$E$30:$E$35)*Instellingen!$P$30:$P$35) -> 10.4 | G17: =SUMPRODUCT((A17>=Instellingen!$F$30:$F$35)*(A17<=Instellingen!$G$30:$G$35)*Instellingen!$Q$30:$Q$35) -> 3.5 | H17: =SUMPRODUCT((A17>=Instellingen!$H$30:$H$35)*(A17<=Instellingen!$I$30:$I$35)*Instellingen!$R$30:$R$35) -> 0 | I17: =SUM(F17:H17) -> 13.9 | J17: =SUM($I$5:I17) -> 72.9 | K17: =IF(Instellingen!$B$4=0,0,J17/Instellingen!$B$4) -> 0.18225
A18: 46362 | B18: zo | C18: =INDEX(Instellingen!$A$30:$A$35,MATCH(A18,Instellingen!$B$30:$B$35,1)) -> F1 Na Black Friday en lijstjestijd | D18: #5 Lijstjesmaand (carrousel) | E18: CHECKPOINT: 27 betaald. Loopt het achter, dan schuift budget van bereik naar retargeting (max 20 % van het weekbudget). | F18: =SUMPRODUCT((A18>=Instellingen!$D$30:$D$35)*(A18<=Instellingen!$E$30:$E$35)*Instellingen!$P$30:$P$35) -> 10.4 | G18: =SUMPRODUCT((A18>=Instellingen!$F$30:$F$35)*(A18<=Instellingen!$G$30:$G$35)*Instellingen!$Q$30:$Q$35) -> 3.5 | H18: =SUMPRODUCT((A18>=Instellingen!$H$30:$H$35)*(A18<=Instellingen!$I$30:$I$35)*Instellingen!$R$30:$R$35) -> 0 | I18: =SUM(F18:H18) -> 13.9 | J18: =SUM($I$5:I18) -> 86.8 | K18: =IF(Instellingen!$B$4=0,0,J18/Instellingen!$B$4) -> 0.217 | M18: Checkpoint 27 betaald
A19: 46363 | B19: ma | C19: =INDEX(Instellingen!$A$30:$A$35,MATCH(A19,Instellingen!$B$30:$B$35,1)) -> F2 Volle agenda | D19: Story-deurtje | E19: BESLISDAG en toets per twee weken 1. Dag-7-check per advertentie (eerlijk aandeel, CTR, kosten per bezoeker). A1 stopt. Eerste winnaar naar de Scaling-campagne. | F19: =SUMPRODUCT((A19>=Instellingen!$D$30:$D$35)*(A19<=Instellingen!$E$30:$E$35)*Instellingen!$P$30:$P$35) -> 9.6571429 | G19: =SUMPRODUCT((A19>=Instellingen!$F$30:$F$35)*(A19<=Instellingen!$G$30:$G$35)*Instellingen!$Q$30:$Q$35) -> 5 | H19: =SUMPRODUCT((A19>=Instellingen!$H$30:$H$35)*(A19<=Instellingen!$I$30:$I$35)*Instellingen!$R$30:$R$35) -> 0 | I19: =SUM(F19:H19) -> 14.657143 | J19: =SUM($I$5:I19) -> 101.45714 | K19: =IF(Instellingen!$B$4=0,0,J19/Instellingen!$B$4) -> 0.25364286 | L19: Beslisdag | M19: Toets 1
A20: 46364 | B20: di | C20: =INDEX(Instellingen!$A$30:$A$35,MATCH(A20,Instellingen!$B$30:$B$35,1)) -> F2 Volle agenda | D20: #9 €3,49 rust (retargeting-ad) | E20: B2 (€3,49 rust) live naast B1. | F20: =SUMPRODUCT((A20>=Instellingen!$D$30:$D$35)*(A20<=Instellingen!$E$30:$E$35)*Instellingen!$P$30:$P$35) -> 9.6571429 | G20: =SUMPRODUCT((A20>=Instellingen!$F$30:$F$35)*(A20<=Instellingen!$G$30:$G$35)*Instellingen!$Q$30:$Q$35) -> 5 | H20: =SUMPRODUCT((A20>=Instellingen!$H$30:$H$35)*(A20<=Instellingen!$I$30:$I$35)*Instellingen!$R$30:$R$35) -> 0 | I20: =SUM(F20:H20) -> 14.657143 | J20: =SUM($I$5:I20) -> 116.11429 | K20: =IF(Instellingen!$B$4=0,0,J20/Instellingen!$B$4) -> 0.29028571
A21: 46365 | B21: wo | C21: =INDEX(Instellingen!$A$30:$A$35,MATCH(A21,Instellingen!$B$30:$B$35,1)) -> F2 Volle agenda | D21: #8 Aftellen naar 31 december, deel 1 (Story) | E21: LANCEERDAG. Zorgverzekering-feiten van idee 8 gecontroleerd? Pas daarna publiceren. Nieuwe test voorbereiden voor het vrijgekomen slot. | F21: =SUMPRODUCT((A21>=Instellingen!$D$30:$D$35)*(A21<=Instellingen!$E$30:$E$35)*Instellingen!$P$30:$P$35) -> 9.6571429 | G21: =SUMPRODUCT((A21>=Instellingen!$F$30:$F$35)*(A21<=Instellingen!$G$30:$G$35)*Instellingen!$Q$30:$Q$35) -> 5 | H21: =SUMPRODUCT((A21>=Instellingen!$H$30:$H$35)*(A21<=Instellingen!$I$30:$I$35)*Instellingen!$R$30:$R$35) -> 0 | I21: =SUM(F21:H21) -> 14.657143 | J21: =SUM($I$5:I21) -> 130.77143 | K21: =IF(Instellingen!$B$4=0,0,J21/Instellingen!$B$4) -> 0.32692857 | L21: Lanceerdag | M21: Feiten idee 8 controleren
A22: 46366 | B22: do | C22: =INDEX(Instellingen!$A$30:$A$35,MATCH(A22,Instellingen!$B$30:$B$35,1)) -> F2 Volle agenda | D22: #7 De volle decemberagenda (Reel) | E22: Organische proef #7 (24 uur). Geen wijziging in lopende advertenties. | F22: =SUMPRODUCT((A22>=Instellingen!$D$30:$D$35)*(A22<=Instellingen!$E$30:$E$35)*Instellingen!$P$30:$P$35) -> 9.6571429 | G22: =SUMPRODUCT((A22>=Instellingen!$F$30:$F$35)*(A22<=Instellingen!$G$30:$G$35)*Instellingen!$Q$30:$Q$35) -> 5 | H22: =SUMPRODUCT((A22>=Instellingen!$H$30:$H$35)*(A22<=Instellingen!$I$30:$I$35)*Instellingen!$R$30:$R$35) -> 0 | I22: =SUM(F22:H22) -> 14.657143 | J22: =SUM($I$5:I22) -> 145.42857 | K22: =IF(Instellingen!$B$4=0,0,J22/Instellingen!$B$4) -> 0.36357143
A23: 46367 | B23: vr | C23: =INDEX(Instellingen!$A$30:$A$35,MATCH(A23,Instellingen!$B$30:$B$35,1)) -> F2 Volle agenda | D23: Story-deurtje | E23: SCHAALDAG. A4 (Agenda) live in Test. Winnaars maximaal +20 %. Is de kosten per start na een stap meer dan 1,5x het doel, dan direct 20 tot 30 % terug. | F23: =SUMPRODUCT((A23>=Instellingen!$D$30:$D$35)*(A23<=Instellingen!$E$30:$E$35)*Instellingen!$P$30:$P$35) -> 9.6571429 | G23: =SUMPRODUCT((A23>=Instellingen!$F$30:$F$35)*(A23<=Instellingen!$G$30:$G$35)*Instellingen!$Q$30:$Q$35) -> 5 | H23: =SUMPRODUCT((A23>=Instellingen!$H$30:$H$35)*(A23<=Instellingen!$I$30:$I$35)*Instellingen!$R$30:$R$35) -> 0 | I23: =SUM(F23:H23) -> 14.657143 | J23: =SUM($I$5:I23) -> 160.08571 | K23: =IF(Instellingen!$B$4=0,0,J23/Instellingen!$B$4) -> 0.40021429 | L23: Schaaldag
A24: 46368 | B24: za | C24: =INDEX(Instellingen!$A$30:$A$35,MATCH(A24,Instellingen!$B$30:$B$35,1)) -> F2 Volle agenda | D24: Story-deurtje | E24: - | F24: =SUMPRODUCT((A24>=Instellingen!$D$30:$D$35)*(A24<=Instellingen!$E$30:$E$35)*Instellingen!$P$30:$P$35) -> 9.6571429 | G24: =SUMPRODUCT((A24>=Instellingen!$F$30:$F$35)*(A24<=Instellingen!$G$30:$G$35)*Instellingen!$Q$30:$Q$35) -> 5 | H24: =SUMPRODUCT((A24>=Instellingen!$H$30:$H$35)*(A24<=Instellingen!$I$30:$I$35)*Instellingen!$R$30:$R$35) -> 0 | I24: =SUM(F24:H24) -> 14.657143 | J24: =SUM($I$5:I24) -> 174.74286 | K24: =IF(Instellingen!$B$4=0,0,J24/Instellingen!$B$4) -> 0.43685714
A25: 46369 | B25: zo | C25: =INDEX(Instellingen!$A$30:$A$35,MATCH(A25,Instellingen!$B$30:$B$35,1)) -> F2 Volle agenda | D25: Story-deurtje | E25: - | F25: =SUMPRODUCT((A25>=Instellingen!$D$30:$D$35)*(A25<=Instellingen!$E$30:$E$35)*Instellingen!$P$30:$P$35) -> 9.6571429 | G25: =SUMPRODUCT((A25>=Instellingen!$F$30:$F$35)*(A25<=Instellingen!$G$30:$G$35)*Instellingen!$Q$30:$Q$35) -> 5 | H25: =SUMPRODUCT((A25>=Instellingen!$H$30:$H$35)*(A25<=Instellingen!$I$30:$I$35)*Instellingen!$R$30:$R$35) -> 0 | I25: =SUM(F25:H25) -> 14.657143 | J25: =SUM($I$5:I25) -> 189.4 | K25: =IF(Instellingen!$B$4=0,0,J25/Instellingen!$B$4) -> 0.4735
A26: 46370 | B26: ma | C26: =INDEX(Instellingen!$A$30:$A$35,MATCH(A26,Instellingen!$B$30:$B$35,1)) -> F3 Vriendenweek en eindsprint | D26: #12 Vriend mee de feestdagen door (Reel) | E26: BESLISDAG. Referral-poort: zijn er 20 of meer klanten? Ja: zet B14 op Ja en start R1 op dinsdag. Nee: budget gaat naar retargeting. | F26: =SUMPRODUCT((A26>=Instellingen!$D$30:$D$35)*(A26<=Instellingen!$E$30:$E$35)*Instellingen!$P$30:$P$35) -> 9.1 | G26: =SUMPRODUCT((A26>=Instellingen!$F$30:$F$35)*(A26<=Instellingen!$G$30:$G$35)*Instellingen!$Q$30:$Q$35) -> 8.1666667 | H26: =SUMPRODUCT((A26>=Instellingen!$H$30:$H$35)*(A26<=Instellingen!$I$30:$I$35)*Instellingen!$R$30:$R$35) -> 0 | I26: =SUM(F26:H26) -> 17.266667 | J26: =SUM($I$5:I26) -> 206.66667 | K26: =IF(Instellingen!$B$4=0,0,J26/Instellingen!$B$4) -> 0.51666667 | L26: Beslisdag | M26: Referral-poort
A27: 46371 | B27: di | C27: =INDEX(Instellingen!$A$30:$A$35,MATCH(A27,Instellingen!$B$30:$B$35,1)) -> F3 Vriendenweek en eindsprint | D27: #11 De kerstkaart van Buddy (static en Story) | E27: R1 (Vriend mee) live, alleen bij Ja op de referral-poort. | F27: =SUMPRODUCT((A27>=Instellingen!$D$30:$D$35)*(A27<=Instellingen!$E$30:$E$35)*Instellingen!$P$30:$P$35) -> 9.1 | G27: =SUMPRODUCT((A27>=Instellingen!$F$30:$F$35)*(A27<=Instellingen!$G$30:$G$35)*Instellingen!$Q$30:$Q$35) -> 8.1666667 | H27: =SUMPRODUCT((A27>=Instellingen!$H$30:$H$35)*(A27<=Instellingen!$I$30:$I$35)*Instellingen!$R$30:$R$35) -> 0 | I27: =SUM(F27:H27) -> 17.266667 | J27: =SUM($I$5:I27) -> 223.93333 | K27: =IF(Instellingen!$B$4=0,0,J27/Instellingen!$B$4) -> 0.55983333
A28: 46372 | B28: wo | C28: =INDEX(Instellingen!$A$30:$A$35,MATCH(A28,Instellingen!$B$30:$B$35,1)) -> F3 Vriendenweek en eindsprint | D28: #8 Aftellen naar 31 december, deel 2 (Story) | E28: LANCEERDAG. Verversing: nieuwe uitvoeringen van het winnende concept (Advent-statics deurtje 3, 9, 14) tegen vermoeidheid. Nooit een draaiende ad aanpassen. | F28: =SUMPRODUCT((A28>=Instellingen!$D$30:$D$35)*(A28<=Instellingen!$E$30:$E$35)*Instellingen!$P$30:$P$35) -> 9.1 | G28: =SUMPRODUCT((A28>=Instellingen!$F$30:$F$35)*(A28<=Instellingen!$G$30:$G$35)*Instellingen!$Q$30:$Q$35) -> 8.1666667 | H28: =SUMPRODUCT((A28>=Instellingen!$H$30:$H$35)*(A28<=Instellingen!$I$30:$I$35)*Instellingen!$R$30:$R$35) -> 0 | I28: =SUM(F28:H28) -> 17.266667 | J28: =SUM($I$5:I28) -> 241.2 | K28: =IF(Instellingen!$B$4=0,0,J28/Instellingen!$B$4) -> 0.603 | L28: Lanceerdag
A29: 46373 | B29: do | C29: =INDEX(Instellingen!$A$30:$A$35,MATCH(A29,Instellingen!$B$30:$B$35,1)) -> F3 Vriendenweek en eindsprint | D29: Story-deurtje | E29: - | F29: =SUMPRODUCT((A29>=Instellingen!$D$30:$D$35)*(A29<=Instellingen!$E$30:$E$35)*Instellingen!$P$30:$P$35) -> 9.1 | G29: =SUMPRODUCT((A29>=Instellingen!$F$30:$F$35)*(A29<=Instellingen!$G$30:$G$35)*Instellingen!$Q$30:$Q$35) -> 8.1666667 | H29: =SUMPRODUCT((A29>=Instellingen!$H$30:$H$35)*(A29<=Instellingen!$I$30:$I$35)*Instellingen!$R$30:$R$35) -> 0 | I29: =SUM(F29:H29) -> 17.266667 | J29: =SUM($I$5:I29) -> 258.46667 | K29: =IF(Instellingen!$B$4=0,0,J29/Instellingen!$B$4) -> 0.64616667
A30: 46374 | B30: vr | C30: =INDEX(Instellingen!$A$30:$A$35,MATCH(A30,Instellingen!$B$30:$B$35,1)) -> F3 Vriendenweek en eindsprint | D30: #10 Kersttafel-bingo (static) | E30: SCHAALDAG. A5 (Bingo) live t/m 22 dec. Laatste dag met nieuwe bereik-uitgaven die nog meetellen voor 19 dec. | F30: =SUMPRODUCT((A30>=Instellingen!$D$30:$D$35)*(A30<=Instellingen!$E$30:$E$35)*Instellingen!$P$30:$P$35) -> 9.1 | G30: =SUMPRODUCT((A30>=Instellingen!$F$30:$F$35)*(A30<=Instellingen!$G$30:$G$35)*Instellingen!$Q$30:$Q$35) -> 8.1666667 | H30: =SUMPRODUCT((A30>=Instellingen!$H$30:$H$35)*(A30<=Instellingen!$I$30:$I$35)*Instellingen!$R$30:$R$35) -> 0 | I30: =SUM(F30:H30) -> 17.266667 | J30: =SUM($I$5:I30) -> 275.73333 | K30: =IF(Instellingen!$B$4=0,0,J30/Instellingen!$B$4) -> 0.68933333 | L30: Schaaldag
A31: 46375 | B31: za | C31: =INDEX(Instellingen!$A$30:$A$35,MATCH(A31,Instellingen!$B$30:$B$35,1)) -> F3 Vriendenweek en eindsprint | D31: Story-deurtje | E31: CHECKPOINT: 35 betaald. Daarna alleen nog retargeting en A5. | F31: =SUMPRODUCT((A31>=Instellingen!$D$30:$D$35)*(A31<=Instellingen!$E$30:$E$35)*Instellingen!$P$30:$P$35) -> 9.1 | G31: =SUMPRODUCT((A31>=Instellingen!$F$30:$F$35)*(A31<=Instellingen!$G$30:$G$35)*Instellingen!$Q$30:$Q$35) -> 8.1666667 | H31: =SUMPRODUCT((A31>=Instellingen!$H$30:$H$35)*(A31<=Instellingen!$I$30:$I$35)*Instellingen!$R$30:$R$35) -> 0 | I31: =SUM(F31:H31) -> 17.266667 | J31: =SUM($I$5:I31) -> 293 | K31: =IF(Instellingen!$B$4=0,0,J31/Instellingen!$B$4) -> 0.7325 | M31: Checkpoint 35 betaald
A32: 46376 | B32: zo | C32: =INDEX(Instellingen!$A$30:$A$35,MATCH(A32,Instellingen!$B$30:$B$35,1)) -> F4 Kerst (na het doel van 19 dec) | D32: Story-deurtje | E32: Alleen A5 en retargeting. CPM-check: duurder dan in week 2? Dan geen extra bereik. | F32: =SUMPRODUCT((A32>=Instellingen!$D$30:$D$35)*(A32<=Instellingen!$E$30:$E$35)*Instellingen!$P$30:$P$35) -> 3.4666667 | G32: =SUMPRODUCT((A32>=Instellingen!$F$30:$F$35)*(A32<=Instellingen!$G$30:$G$35)*Instellingen!$Q$30:$Q$35) -> 3.5 | H32: =SUMPRODUCT((A32>=Instellingen!$H$30:$H$35)*(A32<=Instellingen!$I$30:$I$35)*Instellingen!$R$30:$R$35) -> 0 | I32: =SUM(F32:H32) -> 6.9666667 | J32: =SUM($I$5:I32) -> 299.96667 | K32: =IF(Instellingen!$B$4=0,0,J32/Instellingen!$B$4) -> 0.74991667
A33: 46377 | B33: ma | C33: =INDEX(Instellingen!$A$30:$A$35,MATCH(A33,Instellingen!$B$30:$B$35,1)) -> F4 Kerst (na het doel van 19 dec) | D33: Story-deurtje | E33: BESLISDAG en toets per twee weken 2. Alles lezen. Besluit over het januari-budget op basis van kosten per betaalde abonnee. | F33: =SUMPRODUCT((A33>=Instellingen!$D$30:$D$35)*(A33<=Instellingen!$E$30:$E$35)*Instellingen!$P$30:$P$35) -> 3.4666667 | G33: =SUMPRODUCT((A33>=Instellingen!$F$30:$F$35)*(A33<=Instellingen!$G$30:$G$35)*Instellingen!$Q$30:$Q$35) -> 3.5 | H33: =SUMPRODUCT((A33>=Instellingen!$H$30:$H$35)*(A33<=Instellingen!$I$30:$I$35)*Instellingen!$R$30:$R$35) -> 0 | I33: =SUM(F33:H33) -> 6.9666667 | J33: =SUM($I$5:I33) -> 306.93333 | K33: =IF(Instellingen!$B$4=0,0,J33/Instellingen!$B$4) -> 0.76733333 | L33: Beslisdag | M33: Toets 2
A34: 46378 | B34: di | C34: =INDEX(Instellingen!$A$30:$A$35,MATCH(A34,Instellingen!$B$30:$B$35,1)) -> F4 Kerst (na het doel van 19 dec) | D34: Story-deurtje | E34: A5 (Bingo) stopt om 23:59. | F34: =SUMPRODUCT((A34>=Instellingen!$D$30:$D$35)*(A34<=Instellingen!$E$30:$E$35)*Instellingen!$P$30:$P$35) -> 3.4666667 | G34: =SUMPRODUCT((A34>=Instellingen!$F$30:$F$35)*(A34<=Instellingen!$G$30:$G$35)*Instellingen!$Q$30:$Q$35) -> 3.5 | H34: =SUMPRODUCT((A34>=Instellingen!$H$30:$H$35)*(A34<=Instellingen!$I$30:$I$35)*Instellingen!$R$30:$R$35) -> 0 | I34: =SUM(F34:H34) -> 6.9666667 | J34: =SUM($I$5:I34) -> 313.9 | K34: =IF(Instellingen!$B$4=0,0,J34/Instellingen!$B$4) -> 0.78475
A35: 46379 | B35: wo | C35: =INDEX(Instellingen!$A$30:$A$35,MATCH(A35,Instellingen!$B$30:$B$35,1)) -> F4 Kerst (na het doel van 19 dec) | D35: #8 Aftellen naar 31 december, deel 3 (Story). Story-deurtje | E35: A2 (Advent) stopt om 23:59: laatste deurtje is morgen. | F35: =SUMPRODUCT((A35>=Instellingen!$D$30:$D$35)*(A35<=Instellingen!$E$30:$E$35)*Instellingen!$P$30:$P$35) -> 0 | G35: =SUMPRODUCT((A35>=Instellingen!$F$30:$F$35)*(A35<=Instellingen!$G$30:$G$35)*Instellingen!$Q$30:$Q$35) -> 3.5 | H35: =SUMPRODUCT((A35>=Instellingen!$H$30:$H$35)*(A35<=Instellingen!$I$30:$I$35)*Instellingen!$R$30:$R$35) -> 0 | I35: =SUM(F35:H35) -> 3.5 | J35: =SUM($I$5:I35) -> 317.4 | K35: =IF(Instellingen!$B$4=0,0,J35/Instellingen!$B$4) -> 0.7935 | L35: Lanceerdag
A36: 46380 | B36: do | C36: =INDEX(Instellingen!$A$30:$A$35,MATCH(A36,Instellingen!$B$30:$B$35,1)) -> F4 Kerst (na het doel van 19 dec) | D36: Story-deurtje 24 (feestdagenwens) | E36: Geen wijzigingen. Retargeting loopt op laag budget. | F36: =SUMPRODUCT((A36>=Instellingen!$D$30:$D$35)*(A36<=Instellingen!$E$30:$E$35)*Instellingen!$P$30:$P$35) -> 0 | G36: =SUMPRODUCT((A36>=Instellingen!$F$30:$F$35)*(A36<=Instellingen!$G$30:$G$35)*Instellingen!$Q$30:$Q$35) -> 3.5 | H36: =SUMPRODUCT((A36>=Instellingen!$H$30:$H$35)*(A36<=Instellingen!$I$30:$I$35)*Instellingen!$R$30:$R$35) -> 0 | I36: =SUM(F36:H36) -> 3.5 | J36: =SUM($I$5:I36) -> 320.9 | K36: =IF(Instellingen!$B$4=0,0,J36/Instellingen!$B$4) -> 0.80225 | L36: Schaaldag | M36: Kerstavond
A37: 46381 | B37: vr | C37: =INDEX(Instellingen!$A$30:$A$35,MATCH(A37,Instellingen!$B$30:$B$35,1)) -> F4 Kerst (na het doel van 19 dec) | D37: - | E37: Geen wijzigingen. | F37: =SUMPRODUCT((A37>=Instellingen!$D$30:$D$35)*(A37<=Instellingen!$E$30:$E$35)*Instellingen!$P$30:$P$35) -> 0 | G37: =SUMPRODUCT((A37>=Instellingen!$F$30:$F$35)*(A37<=Instellingen!$G$30:$G$35)*Instellingen!$Q$30:$Q$35) -> 3.5 | H37: =SUMPRODUCT((A37>=Instellingen!$H$30:$H$35)*(A37<=Instellingen!$I$30:$I$35)*Instellingen!$R$30:$R$35) -> 0 | I37: =SUM(F37:H37) -> 3.5 | J37: =SUM($I$5:I37) -> 324.4 | K37: =IF(Instellingen!$B$4=0,0,J37/Instellingen!$B$4) -> 0.811 | M37: Eerste kerstdag
A38: 46382 | B38: za | C38: =INDEX(Instellingen!$A$30:$A$35,MATCH(A38,Instellingen!$B$30:$B$35,1)) -> F5 Januari klaarzetten | D38: #13 Januari staat al klaar (carrousel) | E38: A6 (Januari-carrousel) live in Test. | F38: =SUMPRODUCT((A38>=Instellingen!$D$30:$D$35)*(A38<=Instellingen!$E$30:$E$35)*Instellingen!$P$30:$P$35) -> 5.46 | G38: =SUMPRODUCT((A38>=Instellingen!$F$30:$F$35)*(A38<=Instellingen!$G$30:$G$35)*Instellingen!$Q$30:$Q$35) -> 2.1 | H38: =SUMPRODUCT((A38>=Instellingen!$H$30:$H$35)*(A38<=Instellingen!$I$30:$I$35)*Instellingen!$R$30:$R$35) -> 0 | I38: =SUM(F38:H38) -> 7.56 | J38: =SUM($I$5:I38) -> 331.96 | K38: =IF(Instellingen!$B$4=0,0,J38/Instellingen!$B$4) -> 0.8299
A39: 46383 | B39: zo | C39: =INDEX(Instellingen!$A$30:$A$35,MATCH(A39,Instellingen!$B$30:$B$35,1)) -> F5 Januari klaarzetten | D39: - | E39: - | F39: =SUMPRODUCT((A39>=Instellingen!$D$30:$D$35)*(A39<=Instellingen!$E$30:$E$35)*Instellingen!$P$30:$P$35) -> 5.46 | G39: =SUMPRODUCT((A39>=Instellingen!$F$30:$F$35)*(A39<=Instellingen!$G$30:$G$35)*Instellingen!$Q$30:$Q$35) -> 2.1 | H39: =SUMPRODUCT((A39>=Instellingen!$H$30:$H$35)*(A39<=Instellingen!$I$30:$I$35)*Instellingen!$R$30:$R$35) -> 0 | I39: =SUM(F39:H39) -> 7.56 | J39: =SUM($I$5:I39) -> 339.52 | K39: =IF(Instellingen!$B$4=0,0,J39/Instellingen!$B$4) -> 0.8488
A40: 46384 | B40: ma | C40: =INDEX(Instellingen!$A$30:$A$35,MATCH(A40,Instellingen!$B$30:$B$35,1)) -> F5 Januari klaarzetten | D40: #14 Die rare week (static) | E40: BESLISDAG. Dag-3-cijfers A6: hook rate en CTR. Frequentie controleren. | F40: =SUMPRODUCT((A40>=Instellingen!$D$30:$D$35)*(A40<=Instellingen!$E$30:$E$35)*Instellingen!$P$30:$P$35) -> 5.46 | G40: =SUMPRODUCT((A40>=Instellingen!$F$30:$F$35)*(A40<=Instellingen!$G$30:$G$35)*Instellingen!$Q$30:$Q$35) -> 2.1 | H40: =SUMPRODUCT((A40>=Instellingen!$H$30:$H$35)*(A40<=Instellingen!$I$30:$I$35)*Instellingen!$R$30:$R$35) -> 0 | I40: =SUM(F40:H40) -> 7.56 | J40: =SUM($I$5:I40) -> 347.08 | K40: =IF(Instellingen!$B$4=0,0,J40/Instellingen!$B$4) -> 0.8677 | L40: Beslisdag
A41: 46385 | B41: di | C41: =INDEX(Instellingen!$A$30:$A$35,MATCH(A41,Instellingen!$B$30:$B$35,1)) -> F5 Januari klaarzetten | D41: - | E41: - | F41: =SUMPRODUCT((A41>=Instellingen!$D$30:$D$35)*(A41<=Instellingen!$E$30:$E$35)*Instellingen!$P$30:$P$35) -> 5.46 | G41: =SUMPRODUCT((A41>=Instellingen!$F$30:$F$35)*(A41<=Instellingen!$G$30:$G$35)*Instellingen!$Q$30:$Q$35) -> 2.1 | H41: =SUMPRODUCT((A41>=Instellingen!$H$30:$H$35)*(A41<=Instellingen!$I$30:$I$35)*Instellingen!$R$30:$R$35) -> 0 | I41: =SUM(F41:H41) -> 7.56 | J41: =SUM($I$5:I41) -> 354.64 | K41: =IF(Instellingen!$B$4=0,0,J41/Instellingen!$B$4) -> 0.8866
...

Sheet Advertenties
A1: Advertentielijst en beslissing per advertentie
A2: Teksten komen uit de Ads Manager-secties van de documenten in december/. Vul de blauwe kolommen M t/m P in; Q en R rekenen.
A4: Advertentienaam (utm_content) | B4: Idee | C4: Laag | D4: Campagne | E4: Bestanden (composities) | F4: Start | G4: Eind | H4: Voorwaarde of poort | I4: Primaire tekst (max 125) | J4: Kop (max 40) | K4: Knop | L4: Status | M4: Uitgegeven EUR | N4: LP-weergaven | O4: Starts aanmelding | P4: Aankopen | Q4: Kosten per start | R4: Beslissing
A5: DEC01-Pakketjes-Reel | B5: 1 | C5: Bereik | D5: TOFU-Test | E5: DEC01-Pakketjes-Reel (9:16), DEC01-Pakketjes-Feed (4:5) | F5: 46356 | G5: 46362 | H5: Alleen nadat #1 organisch 8.000+ weergaven en meer dan 30 % 3-seconden-kijkers haalde, of de betaalde hooktest (dag 3) 30 % haalt. Thema verloopt na Black Friday. | I5: Eén dag shoppen, negen dagen betalen. Stuur de betaalmails door en Buddy geeft je seintjes. | J5: Stuur ze door en geniet van je spullen. | K5: Aanmelden | L5: Klaar | Q5: =IF(O5=0,"-",M5/O5) -> - | R5: =IF(M5="","Nog niet gestart",IF(M5<3*Instellingen!$B$9,"WACHT: minder dan 3x doel uitgegeven",IF(O5=0,"VERVANG: nul starts bij 3x doel of meer",IF(M5/O5<=Instellingen!$B$9,"HOUD: kandidaat-winnaar, maximaal +20 % per 5 dagen",IF(M5/O5<=1.5*Instellingen!$B$9,"MONITOR: nog een week","VERVANG of 20 % terug: meer dan 1,5x doel"))))) -> Nog niet gestart
A6: DEC02-Advent-Reel | B6: 2 | C6: Bereik | D6: TOFU-Test, daarna TOFU-Scale | E6: DEC02-Advent-Reel (9:16), DEC02-Advent-Feed (4:5); verversing: DEC02-Advent-Story-03, -09, -14 als statics | F6: 46358 | G6: 46379 | H6: Hero. Zelfde poort als hierboven. Statics als verversing vanaf 16 dec (nooit een draaiende ad aanpassen). | I6: Niet elk deurtje is chocola. Buddy zet je rekeningen in je agenda, met een seintje 7 en 2 dagen vooraf. | J6: Buddy houdt het lijstje bij | K6: Aanmelden | L6: Klaar | Q6: =IF(O6=0,"-",M6/O6) -> - | R6: =IF(M6="","Nog niet gestart",IF(M6<3*Instellingen!$B$9,"WACHT: minder dan 3x doel uitgegeven",IF(O6=0,"VERVANG: nul starts bij 3x doel of meer",IF(M6/O6<=Instellingen!$B$9,"HOUD: kandidaat-winnaar, maximaal +20 % per 5 dagen",IF(M6/O6<=1.5*Instellingen!$B$9,"MONITOR: nog een week","VERVANG of 20 % terug: meer dan 1,5x doel"))))) -> Nog niet gestart
A7: DEC03-Sint-Reel | B7: 3 | C7: Bereik | D7: TOFU-Test | E7: DEC03-Sint-Reel (9:16), DEC03-Sint-Feed (4:5) | F7: 46358 | G7: 46361 | H7: Korte vlucht tot Pakjesavond (5 dec). Wordt niet op kosten per start beoordeeld: te weinig tijd. Alleen hook rate en CTR. | I7: Sint heeft zijn grote boek. Jij hebt Buddy: stuur een rekening door en hij zet de datum in je agenda. | J7: Jij hebt Buddy. | K7: Aanmelden | L7: Klaar | Q7: =IF(O7=0,"-",M7/O7) -> - | R7: =IF(M7="","Nog niet gestart",IF(M7<3*Instellingen!$B$9,"WACHT: minder dan 3x doel uitgegeven",IF(O7=0,"VERVANG: nul starts bij 3x doel of meer",IF(M7/O7<=Instellingen!$B$9,"HOUD: kandidaat-winnaar, maximaal +20 % per 5 dagen",IF(M7/O7<=1.5*Instellingen!$B$9,"MONITOR: nog een week","VERVANG of 20 % terug: meer dan 1,5x doel"))))) -> Nog niet gestart
A8: DEC07-Agenda-Reel | B8: 7 | C8: Bereik | D8: TOFU-Test | E8: DEC07-Agenda-Reel (9:16), DEC07-Agenda-Feed (4:5) | F8: 46367 | G8: 46375 | H8: 24 uur organische proef na post op 10 dec. | I8: Je agenda zit vol. Stuur je rekening door: Buddy zet de datum erin, met seintje 7 en 2 dagen vooraf. | J8: Vol? Buddy maakt nog plek. | K8: Aanmelden | L8: Klaar | Q8: =IF(O8=0,"-",M8/O8) -> - | R8: =IF(M8="","Nog niet gestart",IF(M8<3*Instellingen!$B$9,"WACHT: minder dan 3x doel uitgegeven",IF(O8=0,"VERVANG: nul starts bij 3x doel of meer",IF(M8/O8<=Instellingen!$B$9,"HOUD: kandidaat-winnaar, maximaal +20 % per 5 dagen",IF(M8/O8<=1.5*Instellingen!$B$9,"MONITOR: nog een week","VERVANG of 20 % terug: meer dan 1,5x doel"))))) -> Nog niet gestart
A9: DEC10-Bingo | B9: 10 | C9: Bereik | D9: TOFU-Test | E9: DEC10-Bingo (1080x1350 static) | F9: 46374 | G9: 46378 | H9: Goedkope statics-volume. Laatste bereik-ad vóór kerst. | I9: Kersttafel-bingo. Het middenvak vult Buddy voor je in: "Ja, staat in mijn agenda." | J9: Kersttafel-bingo | K9: Meer informatie | L9: Klaar | Q9: =IF(O9=0,"-",M9/O9) -> - | R9: =IF(M9="","Nog niet gestart",IF(M9<3*Instellingen!$B$9,"WACHT: minder dan 3x doel uitgegeven",IF(O9=0,"VERVANG: nul starts bij 3x doel of meer",IF(M9/O9<=Instellingen!$B$9,"HOUD: kandidaat-winnaar, maximaal +20 % per 5 dagen",IF(M9/O9<=1.5*Instellingen!$B$9,"MONITOR: nog een week","VERVANG of 20 % terug: meer dan 1,5x doel"))))) -> Nog niet gestart
A10: DEC13-Januari-Carrousel | B10: 13 | C10: Bereik | D10: TOFU-Test | E10: DEC13-Januari-1 t/m -6 (carrousel 1080x1350) | F10: 46382 | G10: 46391 | H10: Laagste CPM verwacht in januari: hypothese, meten. | I10: Zorgpremie, termijnen, jaarabonnementen: in januari komt er veel tegelijk. Zet je rekeningen nu klaar. | J10: Januari staat al klaar | K10: Aanmelden | L10: Klaar | Q10: =IF(O10=0,"-",M10/O10) -> - | R10: =IF(M10="","Nog niet gestart",IF(M10<3*Instellingen!$B$9,"WACHT: minder dan 3x doel uitgegeven",IF(O10=0,"VERVANG: nul starts bij 3x doel of meer",IF(M10/O10<=Instellingen!$B$9,"HOUD: kandidaat-winnaar, maximaal +20 % per 5 dagen",IF(M10/O10<=1.5*Instellingen!$B$9,"MONITOR: nog een week","VERVANG of 20 % terug: meer dan 1,5x doel"))))) -> Nog niet gestart
A11: DEC16-Voornemen-Reel | B11: 16 | C11: Bereik | D11: TOFU-Test | E11: DEC16-Voornemen-Reel (9:16), DEC16-Voornemen-Feed (4:5) | F11: 46389 | G11: 46391 | H11: Eerst 24 uur organisch (post 1 jan). De 30-secondenclaim moet eerst gecontroleerd zijn. | I11: Sporten 3 %, eerder naar bed 0 %. Eén mail doorsturen haal je wél in 30 seconden: rekeningen op tijd. | J11: Het voornemen van 30 seconden | K11: Aanmelden | L11: Klaar | Q11: =IF(O11=0,"-",M11/O11) -> - | R11: =IF(M11="","Nog niet gestart",IF(M11<3*Instellingen!$B$9,"WACHT: minder dan 3x doel uitgegeven",IF(O11=0,"VERVANG: nul starts bij 3x doel of meer",IF(M11/O11<=Instellingen!$B$9,"HOUD: kandidaat-winnaar, maximaal +20 % per 5 dagen",IF(M11/O11<=1.5*Instellingen!$B$9,"MONITOR: nog een week","VERVANG of 20 % terug: meer dan 1,5x doel"))))) -> Nog niet gestart
A12: DEC06-Brief | B12: 6 | C12: Retargeting | D12: RT | E12: DEC06-Brief (static 1080x1350) | F12: 46359 | G12: 46387 | H12: Alleen voor sitebezoekers en video-kijkers van de laatste 30 dagen. Vertrouwen is de eerste bezwaren-ad. | I12: Ik ben Rick, maker van Betaalbuddy. Geen bankkoppeling, geen inbox-toegang. Jij stuurt door, Buddy let op de datum. | J12: Een brief van de maker | K12: Meer informatie | L12: Klaar | Q12: =IF(O12=0,"-",M12/O12) -> - | R12: =IF(M12="","Nog niet gestart",IF(M12<3*Instellingen!$B$9,"WACHT: minder dan 3x doel uitgegeven",IF(O12=0,"VERVANG: nul starts bij 3x doel of meer",IF(M12/O12<=Instellingen!$B$9,"HOUD: kandidaat-winnaar, maximaal +20 % per 5 dagen",IF(M12/O12<=1.5*Instellingen!$B$9,"MONITOR: nog een week","VERVANG of 20 % terug: meer dan 1,5x doel"))))) -> Nog niet gestart
A13: DEC09-Rust | B13: 9 | C13: Retargeting | D13: RT | E13: DEC09-Rust (static 1080x1350) | F13: 46364 | G13: 46387 | H13: Prijs alleen hier (Standard). Geen '30 dagen geld terug' tenzij besluit 1 uit het masterplan staat. | I13: Standard kost €3,49 per maand. Stuur een rekening door en Buddy zet het seintje in je agenda. | J13: Rust in december, €3,49 | K13: Meer informatie | L13: Klaar | Q13: =IF(O13=0,"-",M13/O13) -> - | R13: =IF(M13="","Nog niet gestart",IF(M13<3*Instellingen!$B$9,"WACHT: minder dan 3x doel uitgegeven",IF(O13=0,"VERVANG: nul starts bij 3x doel of meer",IF(M13/O13<=Instellingen!$B$9,"HOUD: kandidaat-winnaar, maximaal +20 % per 5 dagen",IF(M13/O13<=1.5*Instellingen!$B$9,"MONITOR: nog een week","VERVANG of 20 % terug: meer dan 1,5x doel"))))) -> Nog niet gestart
A14: DEC12-Vriend-Reel | B14: 12 | C14: Doorverwijzen | D14: REF (voorwaardelijk) | E14: DEC12-Vriend-Reel (9:16), DEC12-Vriend-Feed (4:5) | F14: 46371 | G14: 46375 | H14: Alleen bij 20+ klanten (Instellingen B14 = Ja). Doelgroep: volgers, klanten en betrokken kijkers. Voorwaarden van de werf-aanbieding op de instappagina. | I14: Die ene vriend onder de enveloppen? Stuur hem je link. Wordt hij lid, dan krijg jij een maand gratis. | J14: Vriend mee de feestdagen door | K14: Aanmelden | L14: Klaar | Q14: =IF(O14=0,"-",M14/O14) -> - | R14: =IF(M14="","Nog niet gestart",IF(M14<3*Instellingen!$B$9,"WACHT: minder dan 3x doel uitgegeven",IF(O14=0,"VERVANG: nul starts bij 3x doel of meer",IF(M14/O14<=Instellingen!$B$9,"HOUD: kandidaat-winnaar, maximaal +20 % per 5 dagen",IF(M14/O14<=1.5*Instellingen!$B$9,"MONITOR: nog een week","VERVANG of 20 % terug: meer dan 1,5x doel"))))) -> Nog niet gestart
A16: VOORBEELD (wissen): DEC02-Advent-Reel | M16: 48 | N16: 61 | O16: 3 | P16: 0 | Q16: =M16/O16 -> 16 | R16: Zo ziet een ingevulde regel eruit: EUR 48 uitgegeven, 3 starts is EUR 16 per start: MONITOR.

Sheet Meetplan
A1: Meetplan: elke maandag de week invullen
A2: Meta rapporteert 7 dagen klik. GA4 en Mollie rapporteren anders. Zet de bronnen naast elkaar en tel ze nooit bij elkaar op. De waarheid over betalingen is Mollie/Supabase.
A4: Week | B4: Uitgegeven EUR (Meta) | C4: Vertoningen | D4: 3-sec-weergaven | E4: Linkklikken | F4: LP-weergaven | G4: Starts aanmelding (Meta) | H4: Aankopen (Meta, 7d klik) | I4: Gem. frequentie | J4: Echte bezoekers (GA4, gefilterd) | K4: Nieuwe betalende abonnees (Mollie/Supabase) | L4: CPM | M4: Link-CTR | N4: Hook rate | O4: Kosten per LP-weergave | P4: Kosten per echte bezoeker | Q4: Kosten per start | R4: Kosten per betaalde abonnee (echt) | S4: Bezoeker naar betaald | T4: Status (aanmeldkosten) | U4: Opmerking
A5: VOORBEELD (wissen) | B5: 48 | C5: 6200 | D5: 2100 | E5: 85 | F5: 61 | G5: 3 | H5: 0 | I5: 1.6 | J5: 140 | K5: 3 | L5: =IF(C5>0,B5/C5*1000,"-") -> 7.7419355 | M5: =IF(C5>0,E5/C5,"-") -> 0.013709677 | N5: =IF(C5>0,D5/C5,"-") -> 0.33870968 | O5: =IF(F5>0,B5/F5,"-") -> 0.78688525 | P5: =IF(J5>0,B5/J5,"-") -> 0.34285714 | Q5: =IF(G5>0,B5/G5,"-") -> 16 | R5: =IF(K5>0,B5/K5,"-") -> 16 | S5: =IF(J5>0,K5/J5,"-") -> 0.021428571 | T5: =IF(B5="","-",IF(B5<3*Instellingen!$B$9,"WACHT: te weinig data",IF(G5=0,"VERVANG: nul starts",IF(B5/G5<=Instellingen!$B$9,"OK: onder doel",IF(B5/G5<=1.5*Instellingen!$B$9,"MONITOR","ROOD: boven 1,5x doel"))))) -> MONITOR | U5: Zo ziet een ingevulde week eruit.
A6: Week 1: 30 nov t/m 6 dec | L6: =IF(C6>0,B6/C6*1000,"-") -> - | M6: =IF(C6>0,E6/C6,"-") -> - | N6: =IF(C6>0,D6/C6,"-") -> - | O6: =IF(F6>0,B6/F6,"-") -> - | P6: =IF(J6>0,B6/J6,"-") -> - | Q6: =IF(G6>0,B6/G6,"-") -> - | R6: =IF(K6>0,B6/K6,"-") -> - | S6: =IF(J6>0,K6/J6,"-") -> - | T6: =IF(B6="","-",IF(B6<3*Instellingen!$B$9,"WACHT: te weinig data",IF(G6=0,"VERVANG: nul starts",IF(B6/G6<=Instellingen!$B$9,"OK: onder doel",IF(B6/G6<=1.5*Instellingen!$B$9,"MONITOR","ROOD: boven 1,5x doel"))))) -> -
A7: Week 2: 7 dec t/m 13 dec | L7: =IF(C7>0,B7/C7*1000,"-") -> - | M7: =IF(C7>0,E7/C7,"-") -> - | N7: =IF(C7>0,D7/C7,"-") -> - | O7: =IF(F7>0,B7/F7,"-") -> - | P7: =IF(J7>0,B7/J7,"-") -> - | Q7: =IF(G7>0,B7/G7,"-") -> - | R7: =IF(K7>0,B7/K7,"-") -> - | S7: =IF(J7>0,K7/J7,"-") -> - | T7: =IF(B7="","-",IF(B7<3*Instellingen!$B$9,"WACHT: te weinig data",IF(G7=0,"VERVANG: nul starts",IF(B7/G7<=Instellingen!$B$9,"OK: onder doel",IF(B7/G7<=1.5*Instellingen!$B$9,"MONITOR","ROOD: boven 1,5x doel"))))) -> -
A8: Week 3: 14 dec t/m 19 dec | L8: =IF(C8>0,B8/C8*1000,"-") -> - | M8: =IF(C8>0,E8/C8,"-") -> - | N8: =IF(C8>0,D8/C8,"-") -> - | O8: =IF(F8>0,B8/F8,"-") -> - | P8: =IF(J8>0,B8/J8,"-") -> - | Q8: =IF(G8>0,B8/G8,"-") -> - | R8: =IF(K8>0,B8/K8,"-") -> - | S8: =IF(J8>0,K8/J8,"-") -> - | T8: =IF(B8="","-",IF(B8<3*Instellingen!$B$9,"WACHT: te weinig data",IF(G8=0,"VERVANG: nul starts",IF(B8/G8<=Instellingen!$B$9,"OK: onder doel",IF(B8/G8<=1.5*Instellingen!$B$9,"MONITOR","ROOD: boven 1,5x doel"))))) -> -
A9: Week 4: 20 dec t/m 25 dec | L9: =IF(C9>0,B9/C9*1000,"-") -> - | M9: =IF(C9>0,E9/C9,"-") -> - | N9: =IF(C9>0,D9/C9,"-") -> - | O9: =IF(F9>0,B9/F9,"-") -> - | P9: =IF(J9>0,B9/J9,"-") -> - | Q9: =IF(G9>0,B9/G9,"-") -> - | R9: =IF(K9>0,B9/K9,"-") -> - | S9: =IF(J9>0,K9/J9,"-") -> - | T9: =IF(B9="","-",IF(B9<3*Instellingen!$B$9,"WACHT: te weinig data",IF(G9=0,"VERVANG: nul starts",IF(B9/G9<=Instellingen!$B$9,"OK: onder doel",IF(B9/G9<=1.5*Instellingen!$B$9,"MONITOR","ROOD: boven 1,5x doel"))))) -> -
A10: Week 5: 26 dec t/m 1 jan | L10: =IF(C10>0,B10/C10*1000,"-") -> - | M10: =IF(C10>0,E10/C10,"-") -> - | N10: =IF(C10>0,D10/C10,"-") -> - | O10: =IF(F10>0,B10/F10,"-") -> - | P10: =IF(J10>0,B10/J10,"-") -> - | Q10: =IF(G10>0,B10/G10,"-") -> - | R10: =IF(K10>0,B10/K10,"-") -> - | S10: =IF(J10>0,K10/J10,"-") -> - | T10: =IF(B10="","-",IF(B10<3*Instellingen!$B$9,"WACHT: te weinig data",IF(G10=0,"VERVANG: nul starts",IF(B10/G10<=Instellingen!$B$9,"OK: onder doel",IF(B10/G10<=1.5*Instellingen!$B$9,"MONITOR","ROOD: boven 1,5x doel"))))) -> -
A11: Week 6: 2 jan t/m 4 jan | L11: =IF(C11>0,B11/C11*1000,"-") -> - | M11: =IF(C11>0,E11/C11,"-") -> - | N11: =IF(C11>0,D11/C11,"-") -> - | O11: =IF(F11>0,B11/F11,"-") -> - | P11: =IF(J11>0,B11/J11,"-") -> - | Q11: =IF(G11>0,B11/G11,"-") -> - | R11: =IF(K11>0,B11/K11,"-") -> - | S11: =IF(J11>0,K11/J11,"-") -> - | T11: =IF(B11="","-",IF(B11<3*Instellingen!$B$9,"WACHT: te weinig data",IF(G11=0,"VERVANG: nul starts",IF(B11/G11<=Instellingen!$B$9,"OK: onder doel",IF(B11/G11<=1.5*Instellingen!$B$9,"MONITOR","ROOD: boven 1,5x doel"))))) -> -
A12: Totaal | B12: =SUM(B6:B11) -> 0 | C12: =SUM(C6:C11) -> 0 | D12: =SUM(D6:D11) -> 0 | E12: =SUM(E6:E11) -> 0 | F12: =SUM(F6:F11) -> 0 | G12: =SUM(G6:G11) -> 0 | H12: =SUM(H6:H11) -> 0 | I12: =IF(COUNT(I6:I11)=0,0,AVERAGE(I6:I11)) -> 0 | J12: =SUM(J6:J11) -> 0 | K12: =SUM(K6:K11) -> 0 | L12: =IF(C12>0,B12/C12*1000,"-") -> - | M12: =IF(C12>0,E12/C12,"-") -> - | N12: =IF(C12>0,D12/C12,"-") -> - | O12: =IF(F12>0,B12/F12,"-") -> - | P12: =IF(J12>0,B12/J12,"-") -> - | Q12: =IF(G12>0,B12/G12,"-") -> - | R12: =IF(K12>0,B12/K12,"-") -> - | S12: =IF(J12>0,K12/J12,"-") -> -
A14: Drempels uit het plan (Instellingen): link-CTR minstens 0,8 %, hooguit EUR 1,50 per echte bezoeker, minstens 1 start per EUR 15, minstens 1 aankoop.
A15: Frequentie: koud 1,0 tot 2,5 is veilig, boven 4,0 kritiek. Retargeting 2,0 tot 4,0 is veilig, boven 6,0 kritiek.
A16: De laatste 3 dagen van elke week nooit als eindoordeel gebruiken: conversies lopen tot 72 uur achter.

Sheet Rekensom
A1: Rekensom: wat mag een betalende abonnee kosten?
A3: Basis
A4: Opbrengst per maand excl. btw | B4: =Instellingen!B7 -> 2.8842975 | G4: Aannames: prijs incl. btw, 21 % btw, marge 85 %. Geen retentiecijfers bekend: terugverdientijd is dus de eerlijke maat, geen LTV.
A5: Marge per maand na kosten (aanname) | B5: =B4*Instellingen!B8 -> 2.4516529
A6: Max. kosten per abonnee bij 6 maanden terugverdientijd | B6: =B5*6 -> 14.709917
A7: Max. kosten per abonnee bij 12 maanden terugverdientijd | B7: =B5*12 -> 29.419835
A8: Kosten per abonnee als de pot 13 abonnees oplevert (masterplan) | B8: =Instellingen!B4/13 -> 30.769231 | C8: =B8/B5 -> 12.550403 | D8: maanden terugverdientijd
A9: Eerste maand voor de werver (kosten van één referral) | B9: =B4 -> 2.8842975 | C9: =B9/B5 -> 1.1764706 | D9: maanden terugverdientijd: veel goedkoper dan betaald verkeer
A11: A. Kosten per betaalde abonnee (EUR) | B11: Bezoeker naar betaald:
A12: Kosten per echte bezoeker (rij) / conversie (kolom) | B12: 0.01 | C12: 0.02 | D12: 0.03 | E12: 0.04
A13: 0.4 | B13: =$A13/B$12 -> 40 | C13: =$A13/C$12 -> 20 | D13: =$A13/D$12 -> 13.333333 | E13: =$A13/E$12 -> 10
A14: 0.8 | B14: =$A14/B$12 -> 80 | C14: =$A14/C$12 -> 40 | D14: =$A14/D$12 -> 26.666667 | E14: =$A14/E$12 -> 20
A15: 1.2 | B15: =$A15/B$12 -> 120 | C15: =$A15/C$12 -> 60 | D15: =$A15/D$12 -> 40 | E15: =$A15/E$12 -> 30
A16: 1.5 | B16: =$A16/B$12 -> 150 | C16: =$A16/C$12 -> 75 | D16: =$A16/D$12 -> 50 | E16: =$A16/E$12 -> 37.5
A17: Formule: kosten per bezoeker / conversie van bezoeker naar betaald. Alle getallen zijn gevoeligheidscases, geen voorspelling.
A19: B. Betaalde abonnees uit de hele pot | B19: Bezoeker naar betaald:
A20: Kosten per echte bezoeker (rij) / conversie (kolom) | B20: 0.01 | C20: 0.02 | D20: 0.03 | E20: 0.04
A21: 0.4 | B21: =Instellingen!$B$4/($A21/B$20) -> 10 | C21: =Instellingen!$B$4/($A21/C$20) -> 20 | D21: =Instellingen!$B$4/($A21/D$20) -> 30 | E21: =Instellingen!$B$4/($A21/E$20) -> 40
A22: 0.8 | B22: =Instellingen!$B$4/($A22/B$20) -> 5 | C22: =Instellingen!$B$4/($A22/C$20) -> 10 | D22: =Instellingen!$B$4/($A22/D$20) -> 15 | E22: =Instellingen!$B$4/($A22/E$20) -> 20
A23: 1.2 | B23: =Instellingen!$B$4/($A23/B$20) -> 3.3333333 | C23: =Instellingen!$B$4/($A23/C$20) -> 6.6666667 | D23: =Instellingen!$B$4/($A23/D$20) -> 10 | E23: =Instellingen!$B$4/($A23/E$20) -> 13.333333
A24: 1.5 | B24: =Instellingen!$B$4/($A24/B$20) -> 2.6666667 | C24: =Instellingen!$B$4/($A24/C$20) -> 5.3333333 | D24: =Instellingen!$B$4/($A24/D$20) -> 8 | E24: =Instellingen!$B$4/($A24/E$20) -> 10.666667
A25: Formule: pot / kosten per betaalde abonnee. Het masterplan rekent met ongeveer 13 abonnees uit Meta.
A27: C. Terugverdientijd in maanden | B27: Bezoeker naar betaald:
A28: Kosten per echte bezoeker (rij) / conversie (kolom) | B28: 0.01 | C28: 0.02 | D28: 0.03 | E28: 0.04
A29: 0.4 | B29: =($A29/B$28)/$B$5 -> 16.315523 | C29: =($A29/C$28)/$B$5 -> 8.1577617 | D29: =($A29/D$28)/$B$5 -> 5.4385078 | E29: =($A29/E$28)/$B$5 -> 4.0788808
A30: 0.8 | B30: =($A30/B$28)/$B$5 -> 32.631047 | C30: =($A30/C$28)/$B$5 -> 16.315523 | D30: =($A30/D$28)/$B$5 -> 10.877016 | E30: =($A30/E$28)/$B$5 -> 8.1577617
A31: 1.2 | B31: =($A31/B$28)/$B$5 -> 48.94657 | C31: =($A31/C$28)/$B$5 -> 24.473285 | D31: =($A31/D$28)/$B$5 -> 16.315523 | E31: =($A31/E$28)/$B$5 -> 12.236643
A32: 1.5 | B32: =($A32/B$28)/$B$5 -> 61.183213 | C32: =($A32/C$28)/$B$5 -> 30.591606 | D32: =($A32/D$28)/$B$5 -> 20.394404 | E32: =($A32/E$28)/$B$5 -> 15.295803
A33: Formule: kosten per abonnee / marge per maand. Boven 12 maanden is betaald verkeer zonder bewezen retentie een inzet op leren, niet op rendement.
A35: Conclusie voor dit schema
A36: Zonder retentiedata is EUR 400 een leerbudget. De pot haalt het masterplan-doel van 13 abonnees alleen bij ongeveer EUR 31 per abonnee of lager (zie B8).

Sheet Preflight
A1: Preflight: Go/No-go voor de eerste euro
A2: G0 voor 11 november (vóór de zorgpremie-test van 12 nov), G1 voor 27 november (decemberspecifiek). Eén rood vinkje = geen uitgaven.
A4: ID | B4: Taak | C4: Waarom | D4: Bewijs dat het klopt | E4: Eigenaar | F4: Deadline | G4: Status | H4: Opmerking
A5: G0-1 | B5: Testbetaling met echte iDEAL in de Instagram-browser, iOS en Android, vanuit een echte advertentie-preview | C5: 32 % van het verkeer komt via de Instagram-browser; Clarity zag daar een postMessage-fout. 20 starts gaven 0 betalingen. | D5: Schermopname plus betaling zichtbaar in Mollie en Supabase | E5: Rick | F5: 46337 | G5: Open
A6: G0-2 | B6: Purchase-gebeurtenis via CAPI vanuit de Mollie-webhook, met event_id gelijk aan de betaling en fbp/fbc uit de aanmelding | C6: Aankoop is het enige signaal dat Meta niet kan raden. Browser-redirect alleen is te zwak. | D6: Events Manager > Test Events: 1x Purchase binnen een minuut, waarde 3,49 EUR, ontdubbeld | E6: Rick / Claude | F6: 46337 | G6: Open
A7: G0-3 | B7: InitiateCheckout ('Start aanmelding') en ViewContent op de instappagina | C7: Optimalisatie en retargeting hebben een gebeurtenis boven de aankoop nodig. | D7: Test Events laat beide zien op het juiste moment | E7: Rick / Claude | F7: 46337 | G7: Open
A8: G0-4 | B8: Domein betaalbuddy.nl geverifieerd in Meta | C8: Zonder verificatie zijn conversie-gebeurtenissen beperkt en kan Meta ze afkappen. | D8: Domein toont 'Geverifieerd' in Brand Safety | E8: Rick | F8: 46337 | G8: Open
A9: G0-5 | B9: Cookiebanner laadt de Pixel pas na toestemming en blokkeert de betaling niet | C9: Toestemming is vereist; een banner die checkout blokkeert is een verborgen conversielek. | D9: Test met weigeren en accepteren; Pixel Helper laat het verschil zien | E9: Rick | F9: 46337 | G9: Open
A10: G0-6 | B10: GA4: intern verkeer gefilterd en bots uitgesloten | C10: Veel funnel-events komen van 1 tot 2 gebruikers (eigen tests); Clarity zag 23 % bots. | D10: Filter actief; rapport 'echte bezoekers' klopt met Clarity | E10: Rick | F10: 46337 | G10: Open
A11: G0-7 | B11: Instappagina zegt hetzelfde als de advertentie: geen 'gratis', geen 7 dagen proef, geen WhatsApp of Telegram, wel Standard EUR 3,49 | C11: Meta keurt misleidende of afwijkende landingspagina's af en het vertrouwen is probleem 1. | D11: Homepage, /start-met-betaalbuddy/ en checkout zijn gelezen; /probeer-betaalbuddy/ doorgestuurd | E11: Rick / Claude | F11: 46337 | G11: Open
A12: G0-8 | B12: Besluit over '30 dagen geld terug' | C12: Raakt idee 9 en de pagina. Niet in advertenties tot bevestigd. | D12: Besluit in de changelog | E12: Rick | F12: 46337 | G12: Open
A13: G1-1 | B13: Advertentieaccount: betaalmethode, valuta EUR, tijdzone Amsterdam, uitgavenlimiet gelijk aan de pot | C13: Voorkomt dat een fout meer uitgeeft dan het plan. | D13: Schermafdruk accountinstellingen | E13: Rick | F13: 46352 | G13: Open
A14: G1-2 | B14: Adverteerder geverifieerd voor de EU (handelaarsgegevens, 'Betaald door' en begunstigde) en Instagram en Pagina gekoppeld | C14: In de EU vraagt Meta om deze gegevens. Zonder kan levering stoppen. | D14: Ads Manager toont geen openstaande verificatie | E14: Rick | F14: 46352 | G14: Open
A15: G1-3 | B15: Speciale advertentiecategorie beoordeeld (financiële producten en diensten) | C15: Betaalbuddy leent niet en betaalt niet, maar woorden als 'rekeningen' en 'achteraf betalen' kunnen de classificatie raken. | D15: Keuze vastgelegd; beroepsroute klaar | E15: Rick | F15: 46352 | G15: Open
A16: G1-4 | B16: Aangepaste doelgroepen aangemaakt en groter dan 100: sitebezoekers 30 dagen, startpagina 30 dagen, Start aanmelding 30 dagen, kopers 180 dagen (uitsluiten), Instagram-interactie 90 dagen, video-kijkers 50 % | C16: Retargeting kan alleen starten als de pool er is; kopers moeten uitgesloten worden. | D16: Doelgroepgrootte per lijst genoteerd | E16: Rick | F16: 46349 | G16: Open
... A21: G1-9 | B21: Zorgverzekering-feiten van idee 8 gecontroleerd (Rijksoverheid, zorgverzekeringbesparen.nl) | C21: Staat nog open voor 9 december. | D21: Bronlinks in de doc | E21: Rick | F21: 46364 | G21: Open
B23: Go/No-go | C23: =IF(COUNTIF(G5:G21,"Klaar")=17,"GO: alles klaar","NO-GO: nog "&(17-COUNTIF(G5:G21,"Klaar"))&" regel(s) open") -> NO-GO: nog 17 regel(s) open
